2023-02-15 21:02:47,225 ERROR C:\Users\Home\PycharmProjects\project_dir\venv\lib\site-packages\django\utils\log.py Internal Server Error: /accounts/signup/ (<class 'ValueError'>, ValueError('Invalid address "@yandex.ru"'), <traceback object at 0x0000018A25403E40>)
Traceback (most recent call last):
  File "C:\Users\Home\AppData\Local\Programs\Python\Python310\lib\email\_header_value_parser.py", line 1791, in get_mailbox
    token, value = get_name_addr(value)
  File "C:\Users\Home\AppData\Local\Programs\Python\Python310\lib\email\_header_value_parser.py", line 1767, in get_name_addr
    raise errors.HeaderParseError(
email.errors.HeaderParseError: expected name-addr but found '@yandex.ru'

During handling of the above exception, another exception occurred:

Traceback (most recent call last):
  File "C:\Users\Home\AppData\Local\Programs\Python\Python310\lib\email\_header_value_parser.py", line 1456, in get_local_part
    token, value = get_dot_atom(value)
  File "C:\Users\Home\AppData\Local\Programs\Python\Python310\lib\email\_header_value_parser.py", line 1365, in get_dot_atom
    token, value = get_dot_atom_text(value)
  File "C:\Users\Home\AppData\Local\Programs\Python\Python310\lib\email\_header_value_parser.py", line 1334, in get_dot_atom_text
    raise errors.HeaderParseError("expected atom at a start of "
email.errors.HeaderParseError: expected atom at a start of dot-atom-text but found '@yandex.ru'

During handling of the above exception, another exception occurred:

Traceback (most recent call last):
  File "C:\Users\Home\AppData\Local\Programs\Python\Python310\lib\email\_header_value_parser.py", line 1794, in get_mailbox
    token, value = get_addr_spec(value)
  File "C:\Users\Home\AppData\Local\Programs\Python\Python310\lib\email\_header_value_parser.py", line 1640, in get_addr_spec
    token, value = get_local_part(value)
  File "C:\Users\Home\AppData\Local\Programs\Python\Python310\lib\email\_header_value_parser.py", line 1459, in get_local_part
    token, value = get_word(value)
  File "C:\Users\Home\AppData\Local\Programs\Python\Python310\lib\email\_header_value_parser.py", line 1398, in get_word
    raise errors.HeaderParseError("Expected 'atom' or 'quoted-string' "
email.errors.HeaderParseError: Expected 'atom' or 'quoted-string' but found '@yandex.ru'

During handling of the above exception, another exception occurred:

Traceback (most recent call last):
  File "C:\Users\Home\PycharmProjects\project_dir\venv\lib\site-packages\django\core\mail\message.py", line 82, in sanitize_address
    token, rest = parser.get_mailbox(addr)
  File "C:\Users\Home\AppData\Local\Programs\Python\Python310\lib\email\_header_value_parser.py", line 1796, in get_mailbox
    raise errors.HeaderParseError(
email.errors.HeaderParseError: expected mailbox but found '@yandex.ru'

During handling of the above exception, another exception occurred:

Traceback (most recent call last):
  File "C:\Users\Home\PycharmProjects\project_dir\venv\lib\site-packages\django\core\handlers\exception.py", line 47, in inner
    response = get_response(request)
  File "C:\Users\Home\PycharmProjects\project_dir\venv\lib\site-packages\django\core\handlers\base.py", line 181, in _get_response
    response = wrapped_callback(request, *callback_args, **callback_kwargs)
  File "C:\Users\Home\PycharmProjects\project_dir\venv\lib\site-packages\django\views\generic\base.py", line 70, in view
    return self.dispatch(request, *args, **kwargs)
  File "C:\Users\Home\PycharmProjects\project_dir\venv\lib\site-packages\django\utils\decorators.py", line 43, in _wrapper
    return bound_method(*args, **kwargs)
  File "C:\Users\Home\PycharmProjects\project_dir\venv\lib\site-packages\allauth\decorators.py", line 20, in wrap
    resp = function(request, *args, **kwargs)
  File "C:\Users\Home\PycharmProjects\project_dir\venv\lib\site-packages\django\utils\decorators.py", line 43, in _wrapper
    return bound_method(*args, **kwargs)
  File "C:\Users\Home\PycharmProjects\project_dir\venv\lib\site-packages\django\views\decorators\debug.py", line 89, in sensitive_post_parameters_wrapper
    return view(request, *args, **kwargs)
  File "C:\Users\Home\PycharmProjects\project_dir\venv\lib\site-packages\allauth\account\views.py", line 234, in dispatch
    return super(SignupView, self).dispatch(request, *args, **kwargs)
  File "C:\Users\Home\PycharmProjects\project_dir\venv\lib\site-packages\allauth\account\views.py", line 77, in dispatch
    response = super(RedirectAuthenticatedUserMixin, self).dispatch(
  File "C:\Users\Home\PycharmProjects\project_dir\venv\lib\site-packages\allauth\account\views.py", line 207, in dispatch
    return super(CloseableSignupMixin, self).dispatch(request, *args, **kwargs)
  File "C:\Users\Home\PycharmProjects\project_dir\venv\lib\site-packages\django\views\generic\base.py", line 98, in dispatch
    return handler(request, *args, **kwargs)
  File "C:\Users\Home\PycharmProjects\project_dir\venv\lib\site-packages\allauth\account\views.py", line 105, in post
    response = self.form_valid(form)
  File "C:\Users\Home\PycharmProjects\project_dir\venv\lib\site-packages\allauth\account\views.py", line 254, in form_valid
    return complete_signup(
  File "C:\Users\Home\PycharmProjects\project_dir\venv\lib\site-packages\allauth\account\utils.py", line 186, in complete_signup
    return perform_login(
  File "C:\Users\Home\PycharmProjects\project_dir\venv\lib\site-packages\allauth\account\utils.py", line 168, in perform_login
    response = adapter.pre_login(request, user, **hook_kwargs)
  File "C:\Users\Home\PycharmProjects\project_dir\venv\lib\site-packages\allauth\account\adapter.py", line 412, in pre_login
    send_email_confirmation(request, user, signup=signup, email=email)
  File "C:\Users\Home\PycharmProjects\project_dir\venv\lib\site-packages\allauth\account\utils.py", line 319, in send_email_confirmation
    email_address.send_confirmation(request, signup=signup)
  File "C:\Users\Home\PycharmProjects\project_dir\venv\lib\site-packages\allauth\account\models.py", line 59, in send_confirmation
    confirmation.send(request, signup=signup)
  File "C:\Users\Home\PycharmProjects\project_dir\venv\lib\site-packages\allauth\account\models.py", line 166, in send
    get_adapter(request).send_confirmation_mail(request, self, signup)
  File "C:\Users\Home\PycharmProjects\project_dir\venv\lib\site-packages\allauth\account\adapter.py", line 549, in send_confirmation_mail
    self.send_mail(email_template, emailconfirmation.email_address.email, ctx)
  File "C:\Users\Home\PycharmProjects\project_dir\venv\lib\site-packages\allauth\account\adapter.py", line 140, in send_mail
    msg.send()
  File "C:\Users\Home\PycharmProjects\project_dir\venv\lib\site-packages\django\core\mail\message.py", line 284, in send
    return self.get_connection(fail_silently).send_messages([self])
  File "C:\Users\Home\PycharmProjects\project_dir\venv\lib\site-packages\django\core\mail\backends\smtp.py", line 109, in send_messages
    sent = self._send(message)
  File "C:\Users\Home\PycharmProjects\project_dir\venv\lib\site-packages\django\core\mail\backends\smtp.py", line 121, in _send
    from_email = sanitize_address(email_message.from_email, encoding)
  File "C:\Users\Home\PycharmProjects\project_dir\venv\lib\site-packages\django\core\mail\message.py", line 84, in sanitize_address
    raise ValueError('Invalid address "%s"' % addr)
ValueError: Invalid address "@yandex.ru"
2023-02-15 21:02:47,568 ERROR C:\Users\Home\PycharmProjects\project_dir\venv\lib\site-packages\django\core\servers\basehttp.py "POST /accounts/signup/ HTTP/1.1" 500 222609 None
